Workbook

Sheet INICIO
C2: SUSAN DANIELA RIVERA TORREALBA
C3: C.C. 1.140.418.986

Sheet EGRESOS 
C2: SUSAN DANIELA RIVERA TORREALBA
C3: C.C. 1.140.418.986
C4: CONTROL DE EGRESOS
C8: DIA | D8: TERCERO | E8: DESCRIPCION | F8: COSTOS | G8: G. PERSONAL | H8: G. SERVICIOS | I8: OTROS GASTOS | J8: DEPOSITOS | K8: TOTAL DIA | L8: TOTAL MES
C9: 1 | D9: FRUTAS EL PAISA | E9: COMPRA DE INSUMOS | F9: 55000 | G9: 0 | H9: 0 | I9: 0 | K9: 0 | P9: NIT ó CC | Q9: Columna1
D10: ARA | E10: COMPRA DE INSUMOS | F10: 49880 | G10: 0 | H10: 0 | I10: 0 | K10: 0 | Q10: TERCEROS
D11: D1 | E11: COMPRA DE INSUMOS | F11: 22850 | G11: 0 | H11: 0 | I11: 0 | K11: 0 | Q11: (OSO) DISTRIBUCIONES 2A SAS
D12: KARINA PEREZ | E12: PAGO TURNO MAÑANA | F12: 0 | G12: 50000 | H12: 0 | I12: 0 | K12: 0 | Q12: AGUA ESSENCIA
D13: HIELO LA ROCA | E13: COMPRA DE INSUMOS | F13: 10000 | G13: 0 | H13: 0 | I13: 0 | K13: 0 | Q13: AIR-E
D14: DON TOMATO | E14: COMPRA DE INSUMOS | F14: 36736 | G14: 0 | H14: 0 | I14: 0 | K14: 0 | Q14: ALMACEN ELECTROSAN
D15: (OSO) DISTRIBUCIONES 2A SAS | E15: COMPRA DE INSUMOS | F15: 46600 | G15: 0 | H15: 0 | I15: 0 | K15: 0 | Q15: ALMACENES D1
D16: FRUTAS EL PAISA | E16: COMPRA DE INSUMOS | F16: 70800 | G16: 0 | H16: 0 | I16: 0 | K16: 0 | Q16: APORTES EN LINEA
D17: THAIS MERCADO | E17: PAGO TURNO TARDE | F17: 0 | G17: 55000 | H17: 0 | I17: 0 | K17: 0 | Q17: ARA
D18: THAIS MERCADO | E18: PAGO PREMIO PRIMER PUESTO | F18: 0 | G18: 50000 | H18: 0 | I18: 0 | K18: 0 | Q18: BIMBO
F19: 0 | G19: 0 | H19: 0 | I19: 0 | K19: 0 | Q19: CACHARRERIA CLAUDIA
F20: 0 | G20: 0 | H20: 0 | I20: 0 | K20: 0 | Q20: CHALOS
F21: 0 | G21: 0 | H21: 0 | I21: 0 | K21: 0 | Q21: CLARO
F22: 0 | G22: 0 | H22: 0 | I22: 0 | K22: 0 | Q22: COCA COLA
F23: 0 | G23: 0 | H23: 0 | I23: 0 | K23: 0 | L23: =SUM(F9:G13) -> 187730 | Q23: COLOMBINA
F24: 0 | G24: 0 | H24: 0 | I24: 0 | K24: 0 | L24: =SUM(F14:F16)+G17+G18 -> 259136 | Q24: COMERCIALIZADORA BIOSTIVEN
E25: TOTALES | F25: =SUM(F9:F24) -> 291866 | G25: =SUM(G9:G24) -> 155000 | H25: =SUM(H9:H24) -> 0 | I25: =SUM(I9:I24) -> 0 | J25: =SUM(J9:J24) -> 0 | K25: =SUM(F25:J25)-J25 -> 446866 | Q25: CONSTRUMATERIALES LA FORTUNA
C26: 2 | D26: H2O BRISAS DE MANGLARES | E26: COMPRA DE INSUMOS | F26: 10000 | G26: 0 | H26: 0 | I26: 0 | K26: 0 | Q26: D1
D27: CHALOS | E27: COMPRA DE INSUMOS | F27: 113500 | G27: 0 | H27: 0 | I27: 0 | K27: 0 | Q27: DISTRIBUIDORA BUCARAMANGA
D28: OLIMPICA | E28: COMPRA DE INSUMOS | F28: 61990 | G28: 0 | H28: 0 | I28: 0 | K28: 0 | Q28: DISTRIBUIDORA DON TOMATO
D29: KARINA PEREZ | E29: PAGO TURNO MAÑANA | F29: 0 | G29: 50000 | H29: 0 | I29: 0 | K29: 0 | Q29: DISTRIPLASTICO LUCY
D30: ANA CERVANTES | E30: PAGO TURNO TARDE | F30: 0 | G30: 65000 | H30: 0 | I30: 0 | K30: 0 | Q30: DÓLAR CITY
D31: FRUTAS EL PAISA | E31: COMPRA DE INSUMOS | F31: 46000 | G31: 0 | H31: 0 | I31: 0 | K31: 0 | Q31: DOMICILIO
F32: 0 | G32: 0 | H32: 0 | I32: 0 | K32: 0 | Q32: DONDE LUCY
F33: 0 | G33: 0 | H33: 0 | I33: 0 | K33: 0 | Q33: DOXA
F34: 0 | G34: 0 | H34: 0 | I34: 0 | K34: 0 | Q34: FRUVER ALVEG SAS
F35: 0 | G35: 0 | I35: 0 | K35: 0 | Q35: FULL HOGAR
F36: 0 | G36: 0 | H36: 0 | I36: 0 | K36: 0 | Q36: GASES DEL CARIBE
F37: 0 | G37: 0 | H37: 0 | I37: 0 | K37: 0 | Q37: HELADOS COLOMBIA
F38: 0 | G38: 0 | H38: 0 | I38: 0 | K38: 0 | Q38: HIELO LA ROCA
F39: 0 | G39: 0 | H39: 0 | I39: 0 | K39: 0 | Q39: HOTEL CHAYRAMA
F40: 0 | G40: 0 | H40: 0 | I40: 0 | K40: 0 | L40: =SUM(F26:G29) -> 235490 | Q40: ISMAR TORREALBA
F41: 0 | G41: 0 | H41: 0 | I41: 0 | K41: 0 | L41: =SUM(G30+F31) -> 111000 | Q41: JAIRO LOPEZ
F42: 0 | G42: 0 | H42: 0 | I42: 0 | K42: 0 | Q42: JOSE RIVERA
E43: TOTALES | F43: =SUM(F26:F42) -> 231490 | G43: =SUM(G26:G42) -> 115000 | H43: =SUM(H26:H42) -> 0 | I43: =SUM(I26:I42) -> 0 | J43: =SUM(J26:J42) -> 0 | K43: =SUM(F43:J43)-J43 -> 346490 | Q43: JULIAN RIVERA
C44: 3 | D44: HIELO LA ROCA | E44: COMPRA DE INSUMOS | F44: 10000 | G44: 0 | H44: 0 | I44: 0 | K44: 0 | Q44: KARINA PEREZ
...

Sheet RESUMEN MES
C2: =+'EGRESOS '!G7 -> 0
C3: VENTAS
C4: EFECTIVO | D4: =+VENTAS!$E$10+VENTAS!$E$13+VENTAS!$E$16+VENTAS!$E$19+VENTAS!$E$22+VENTAS!$E$25+VENTAS!$E$28+VENTAS!$E$31+VENTAS!$E$34+VENTAS!$E$37+VENTAS!$E$40+VENTAS!$E$43+VENTAS!$E$46+VENTAS!$E$49+VENTAS!$E$52+VENTAS!$E$55+VENTAS!$E$58+VENTAS!$E$61+VENTAS!$E$64+VENTAS!$E$67+VENTAS!$E$70+VENTAS!$E$73+VENTAS!$E$76+VENTAS!$E$79+VENTAS!$E$82++VENTAS!$E$85+VENTAS!$E$88+VENTAS!$E$91+VENTAS!$E$94+VENTAS!$E$97+VENTAS!$E$100 -> 14187600
C5: TARJETA | D5: =+VENTAS!$E$11+VENTAS!$E$14+VENTAS!$E$17+VENTAS!$E$20+VENTAS!$E$23+VENTAS!$E$26+VENTAS!$E$29+VENTAS!$E$32+VENTAS!$E$35+VENTAS!$E$38+VENTAS!$E$41+VENTAS!$E$44+VENTAS!$E$47+VENTAS!$E$50+VENTAS!$E$53+VENTAS!$E$56+VENTAS!$E$59+VENTAS!$E$62+VENTAS!$E$65+VENTAS!$E$68+VENTAS!$E$71+VENTAS!$E$74+VENTAS!$E$77+VENTAS!$E$80+VENTAS!$E$83+VENTAS!$E$86+VENTAS!$E$89+VENTAS!$E$92+VENTAS!$E$95+VENTAS!$E$98+VENTAS!$E$101 -> 5972100
C6: TOTAL MES | D6: =+D4+D5 -> 20159700
C12: GASTOS Y SERVICIOS | E12: COMPRAS | F12: PERSONAL | G12: SERVICIOS | H12: OTROS GASTOS | I12: TOTAL GASTOS MES
C13: TOTALES | E13: =+'EGRESOS '!F562 -> 8704937 | F13: =+'EGRESOS '!G562 -> 4104000 | G13: =+'EGRESOS '!H562 -> 2930142 | H13: =+'EGRESOS '!I562 -> 627500 | I13: =SUM(E13:H13) -> 16366579
C14: PORCENTAJE SOBRE EL TOTAL DE LOS GASTOS | E14: =+IFERROR(E13/I13,"revisar") -> 0.53187273 | F14: =+IFERROR(F13/I13,"revisar") -> 0.25075491 | G14: =+IFERROR(G13/I13,"revisar") -> 0.17903204 | H14: =+IFERROR(H13/I13,"revisar") -> 0.038340328 | I14: =SUM(E14:H14) -> 1
C15: INGRESO AUTO
C16: PAGOS CON RETIROS
C17: TOTAL AHORROS
C21: RESUMEN MES
C22: INGRESOS | D22: =+'LIBRO DIARIO'!D39 -> 20159700
C23: GASTOS Y COSTOS | D23: =+'LIBRO DIARIO'!E39 -> 16366579 | E23: =IFERROR(D23/D22,"revisar") -> 0.81184636 | F23: PORCENTAJE DE GASTOS SOBRE LAS VENTAS
C24: GANCIA O PERDIDA OPERATIVA | D24: =+D22-D23 -> 3793121 | E24: =IFERROR(D24/D22,"revisar") -> 0.18815364 | F24: PORCENTAJE DE UTILIDAD OPERATIVA SOBRE LAS VENTAS (NO SE INCLUYE IMPUESTOS)
C26: ACCESORIOS TOTAL | D26: =+ACCESORIOS!D405 -> 40000
C27: ACCESORIOS CAJA FUERTE | D27: =+SUMIF('CAJA FUERTE'!B6:D191,'CAJA FUERTE'!B11:B12,'CAJA FUERTE'!C6:C192)-SUMIF('CAJA FUERTE'!B6:D191,'CAJA FUERTE'!B11,'CAJA FUERTE'!D6:D192) -> 0
C28: FONDO R | D28: =+SUMIF('CAJA FUERTE'!$B$6:$F$191,'RESUMEN MES'!C28,'CAJA FUERTE'!$C$6:I21)-SUMIF('CAJA FUERTE'!B6:E191,'RESUMEN MES'!C28,'CAJA FUERTE'!D6:D191) -> 0
C29: CAJA FUERTE | D29: =+'CAJA FUERTE'!F193 -> 415310
C31: GASTOS | D31: MONTO | E31: 100
C32: COLOMBINA | D32: =+SUMIF('EGRESOS '!$D$9:$F$559,'RESUMEN MES'!C32,'EGRESOS '!$F$9:$F$559) -> 219811 | E32: =+IFERROR((D32*$E$31)/$E$13,"SIN DATOS") -> 2.5251303
C33: SURTIMERCAR LA 13 | D33: =+SUMIF('EGRESOS '!$D$9:$F$559,'RESUMEN MES'!C33,'EGRESOS '!$F$9:$F$559) -> 1704150 | E33: =+IFERROR((D33*$E$31)/$E$13,"SIN DATOS") -> 19.576822
C34: MAKRO | D34: =+SUMIF('EGRESOS '!$D$9:$F$559,'RESUMEN MES'!C34,'EGRESOS '!$F$9:$F$559) -> 1077877 | E34: =+IFERROR((D34*$E$31)/$E$13,"SIN DATOS") -> 12.382364
C35: CHALOS | D35: =+SUMIF('EGRESOS '!$D$9:$F$559,'RESUMEN MES'!C35,'EGRESOS '!$F$9:$F$559) -> 1533900 | E35: =+IFERROR((D35*$E$31)/$E$13,"SIN DATOS") -> 17.621035
C36: HIELO LA ROCA | D36: =+SUMIF('EGRESOS '!$D$9:$F$559,'RESUMEN MES'!C36,'EGRESOS '!$F$9:$F$559) -> 190000 | E36: =+IFERROR((D36*$E$31)/$E$13,"SIN DATOS") -> 2.1826694
C37: (OSO) DISTRIBUCIONES 2A SAS | D37: =+SUMIF('EGRESOS '!$D$9:$F$559,'RESUMEN MES'!C37,'EGRESOS '!$F$9:$F$559) -> 275375 | E37: =+IFERROR((D37*$E$31)/$E$13,"SIN DATOS") -> 3.1634347
C38: OLIMPICA | D38: =+SUMIF('EGRESOS '!$D$9:$F$559,'RESUMEN MES'!C38,'EGRESOS '!$F$9:$F$559) -> 542578 | E38: =+IFERROR((D38*$E$31)/$E$13,"SIN DATOS") -> 6.2329917
C39: ARA | D39: =+SUMIF('EGRESOS '!$D$9:$F$559,'RESUMEN MES'!C39,'EGRESOS '!$F$9:$F$559) -> 875743 | E39: =+IFERROR((D39*$E$31)/$E$13,"SIN DATOS") -> 10.060303
C40: D1 | D40: =+SUMIF('EGRESOS '!$D$9:$F$559,'RESUMEN MES'!C40,'EGRESOS '!$F$9:$F$559) -> 182690 | E40: =+IFERROR((D40*$E$31)/$E$13,"SIN DATOS") -> 2.0986941
C41: MULTIMARCAS DEL CARIBE | D41: =+SUMIF('EGRESOS '!$D$9:$F$559,'RESUMEN MES'!C41,'EGRESOS '!$F$9:$F$559) -> 371155 | E41: =+IFERROR((D41*$E$31)/$E$13,"SIN DATOS") -> 4.2637299
C42: COCA COLA | D42: =+SUMIF('EGRESOS '!$D$9:$F$559,'RESUMEN MES'!C42,'EGRESOS '!$F$9:$F$559) -> 220600 | E42: =+IFERROR((D42*$E$31)/$E$13,"SIN DATOS") -> 2.5341941
C43: RAPIMERCAR | D43: =+SUMIF('EGRESOS '!$D$9:$F$559,'RESUMEN MES'!C43,'EGRESOS '!$F$9:$F$559) -> 0 | E43: =+IFERROR((D43*$E$31)/$E$13,"SIN DATOS") -> 0
C44: FRUTAS EL PAISA | D44: =+SUMIF('EGRESOS '!$D$9:$F$559,'RESUMEN MES'!C44,'EGRESOS '!$F$9:$F$559) -> 653500 | E44: =+IFERROR((D44*$E$31)/$E$13,"SIN DATOS") -> 7.5072341 | G44: l
C45: H2O BRISAS DE MANGLARES | D45: =+SUMIF('EGRESOS '!$D$9:$F$559,'RESUMEN MES'!C45,'EGRESOS '!$F$9:$F$559) -> 60000 | E45: =+IFERROR((D45*$E$31)/$E$13,"SIN DATOS") -> 0.68926403
C46: MERCADO CAMPESINO LA CENTRAL | D46: =+SUMIF('EGRESOS '!$D$9:$F$559,'RESUMEN MES'!C46,'EGRESOS '!$F$9:$F$559) -> 301400 | E46: =+IFERROR((D46*$E$31)/$E$13,"SIN DATOS") -> 3.462403
C47: MULTIMARCAS DEL CARIBE | D47: =+SUMIF('EGRESOS '!$D$9:$F$559,'RESUMEN MES'!C47,'EGRESOS '!$F$9:$F$559) -> 371155 | E47: =+IFERROR((D47*$E$31)/$E$13,"SIN DATOS") -> 4.2637299

Sheet VENTAS
C3: SUSAN DANIELA RIVERA TORREALBA
C4: C.C.1.140.418.986
C5: VENTAS
G7: =+'EGRESOS '!G7 -> 0
C9: DIA | D9: FORMA | E9: MONTO | F9: INGRE AUT | G9: EGRESO | H9: SALDO | I9: NOVEDAD
C10: 1 | D10: EFECTIVO | E10: =125000+378500 -> 503500
C11: 1 | D11: TARJETA | E11: =47000+42000+17000 -> 106000
C12: TOTAL | E12: =SUM(E10:E11) -> 609500 | F12: =SUM(F10:F11) -> 0 | G12: =+'EGRESOS '!K25 -> 446866 | H12: =+E12-G12 -> 162634
C13: 2 | D13: EFECTIVO | E13: 552500
C14: 2 | D14: TARJETA | E14: =13000+76500+199200 -> 288700
C15: TOTAL | E15: =SUM(E13:E14) -> 841200 | F15: =SUM(F13:F14) -> 0 | G15: =+'EGRESOS '!K43 -> 346490 | H15: =+H12+E15-G15 -> 657344
C16: 3 | D16: EFECTIVO | E16: =94000+648000 -> 742000
C17: 3 | D17: TARJETA | E17: =129000+42000 -> 171000
C18: TOTAL | E18: =SUM(E16:E17) -> 913000 | F18: =SUM(F16:F17) -> 0 | G18: =+'EGRESOS '!K61 -> 595160 | H18: =+H15+E18-G18 -> 975184
C19: 4 | D19: EFECTIVO | E19: =113700+534500 -> 648200
C20: 4 | D20: TARJETA | E20: =115000+181000 -> 296000
C21: TOTAL | E21: =SUM(E19:E20) -> 944200 | F21: =SUM(F19:F20) -> 0 | G21: =+'EGRESOS '!K77 -> 456456 | H21: =+H18+E21-G21 -> 1462928
C22: 5 | D22: EFECTIVO | E22: =199000+368000 -> 567000
C23: 5 | D23: TARJETA | E23: =84000+252000 -> 336000
C24: TOTAL | E24: =SUM(E22:E23) -> 903000 | F24: =SUM(F22:F23) -> 0 | G24: =+'EGRESOS '!K95 -> 525100 | H24: =+H21+E24-G24 -> 1840828
C25: 6 | D25: EFECTIVO | E25: =17000+84000 -> 101000
C26: 6 | D26: TARJETA | E26: =59000+126700 -> 185700
C27: TOTAL | E27: =SUM(E25:E26) -> 286700 | F27: =SUM(F25:F26) -> 0 | G27: =+'EGRESOS '!K113 -> 787617 | H27: =+H24+E27-G27 -> 1339911
C28: 7 | D28: EFECTIVO | E28: =125000+299000 -> 424000
C29: 7 | D29: TARJETA | E29: =78000+117000 -> 195000
C30: TOTAL | E30: =SUM(E28:E29) -> 619000 | F30: =SUM(F28:F29) -> 0 | G30: =+'EGRESOS '!K130 -> 170325 | H30: =+H27+E30-G30 -> 1788586
C31: 8 | D31: EFECTIVO | E31: 387000
C32: 8 | D32: TARJETA | E32: 165000
C33: TOTAL | E33: =SUM(E31:E32) -> 552000 | F33: =SUM(F31:F32) -> 0 | G33: =+'EGRESOS '!K148 -> 2594022 | H33: =+H30+E33-G33 -> -253436
C34: 9 | D34: EFECTIVO | E34: 599500
C35: 9 | D35: TARJETA | E35: 128000
C36: TOTAL | E36: =SUM(E34:E35) -> 727500 | F36: =SUM(F34:F35) -> 0 | G36: =+'EGRESOS '!K167 -> 396358 | H36: =+H33+E36-G36 -> 77706
C37: 10 | D37: EFECTIVO | E37: =200000+423000 -> 623000
C38: 10 | D38: TARJETA | E38: =14500+125500 -> 140000
C39: TOTAL | E39: =SUM(E37:E38) -> 763000 | F39: =SUM(F37:F38) -> 0 | G39: =+'EGRESOS '!K184 -> 332880 | H39: =+H36+E39-G39 -> 507826
C40: 11 | D40: EFECTIVO | E40: =272500+442000 -> 714500
C41: 11 | D41: TARJETA | E41: =168000+167500 -> 335500
C42: TOTAL | E42: =SUM(E40:E41) -> 1050000 | F42: =SUM(F40:F41) -> 0 | G42: =+'EGRESOS '!K202 -> 652308 | H42: =+H39+E42-G42 -> 905518
C43: 12 | D43: EFECTIVO | E43: =198500+349000 -> 547500
C44: 12 | D44: TARJETA | E44: =73000+58000 -> 131000
...

Sheet LIBRO DIARIO
C2: SUSAN DANIELA RIVERA TORREALBA | R2: 100000
C3: C.C.1.140.418.986 | R3: 300000
C4: LIBRO DIARIO | R4: 400000
R5: 500000
E6: =+'EGRESOS '!G7 -> 0 | R6: 600000
C7: DIA | D7: VENTAS | E7: EGRESOS | F7: SALDO | R7: 700000
C8: 1 | D8: =+VENTAS!E12 -> 609500 | E8: =+VENTAS!G12 -> 446866 | F8: =+D8-E8 -> 162634 | R8: 800000
C9: 2 | D9: =+VENTAS!E15 -> 841200 | E9: =+VENTAS!G15 -> 346490 | F9: =+F8+D9-E9 -> 657344 | R9: 900000
C10: 3 | D10: =+VENTAS!E18 -> 913000 | E10: =+VENTAS!G18 -> 595160 | F10: =+F9+D10-E10 -> 975184 | R10: 1000000
C11: 4 | D11: =+VENTAS!E21 -> 944200 | E11: =+VENTAS!G21 -> 456456 | F11: =+F10+D11-E11 -> 1462928 | R11: 1100000
C12: 5 | D12: =+VENTAS!E24 -> 903000 | E12: =+VENTAS!G24 -> 525100 | F12: =+F11+D12-E12 -> 1840828 | R12: 1200000
C13: 6 | D13: =+VENTAS!E27 -> 286700 | E13: =+VENTAS!G27 -> 787617 | F13: =+F12+D13-E13 -> 1339911 | R13: 1300000
C14: 7 | D14: =+VENTAS!E30 -> 619000 | E14: =+VENTAS!G30 -> 170325 | F14: =+F13+D14-E14 -> 1788586 | R14: 1400000
C15: 8 | D15: =+VENTAS!E33 -> 552000 | E15: =+VENTAS!G33 -> 2594022 | F15: =+F14+D15-E15 -> -253436 | R15: 1500000
C16: 9 | D16: =+VENTAS!E36 -> 727500 | E16: =+VENTAS!G36 -> 396358 | F16: =+F15+D16-E16 -> 77706 | R16: 0
C17: 10 | D17: =+VENTAS!E39 -> 763000 | E17: =+VENTAS!G39 -> 332880 | F17: =+F16+D17-E17 -> 507826
C18: 11 | D18: =+VENTAS!E42 -> 1050000 | E18: =+VENTAS!G42 -> 652308 | F18: =+F17+D18-E18 -> 905518
C19: 12 | D19: =+VENTAS!E45 -> 678500 | E19: =+VENTAS!G45 -> 861644 | F19: =+F18+D19-E19 -> 722374
C20: 13 | D20: =+VENTAS!E48 -> 426800 | E20: =+VENTAS!G48 -> 711097 | F20: =+F19+D20-E20 -> 438077
C21: 14 | D21: =+VENTAS!E51 -> 468500 | E21: =+VENTAS!G51 -> 483836 | F21: =+F20+D21-E21 -> 422741
C22: 15 | D22: =+VENTAS!E54 -> 606700 | E22: =+VENTAS!G54 -> 216500 | F22: =+F21+D22-E22 -> 812941
C23: 16 | D23: =+VENTAS!E57 -> 278500 | E23: =+VENTAS!G57 -> 299070 | F23: =+F22+D23-E23 -> 792371
C24: 17 | D24: =+VENTAS!E60 -> 396000 | E24: =+VENTAS!G60 -> 219270 | F24: =+F23+D24-E24 -> 969101
C25: 18 | D25: =+VENTAS!E63 -> 1101900 | E25: =+VENTAS!G63 -> 347810 | F25: =+F24+D25-E25 -> 1723191
C26: 19 | D26: =+VENTAS!E66 -> 314500 | E26: =+VENTAS!G66 -> 461691 | F26: =+F25+D26-E26 -> 1576000
C27: 20 | D27: =+VENTAS!E69 -> 405000 | E27: =+VENTAS!G69 -> 483064 | F27: =+F26+D27-E27 -> 1497936
C28: 21 | D28: =+VENTAS!E72 -> 618600 | E28: =+VENTAS!G72 -> 323790 | F28: =+F27+D28-E28 -> 1792746
C29: 22 | D29: =+VENTAS!E75 -> 518000 | E29: =+VENTAS!G75 -> 320037 | F29: =+F28+D29-E29 -> 1990709
C30: 23 | D30: =+VENTAS!E78 -> 807800 | E30: =+VENTAS!G78 -> 272010 | F30: =+F29+D30-E30 -> 2526499
C31: 24 | D31: =+VENTAS!E81 -> 660400 | E31: =+VENTAS!G81 -> 540681 | F31: =+F30+D31-E31 -> 2646218
C32: 25 | D32: =+VENTAS!E84 -> 756900 | E32: =+VENTAS!G84 -> 962413 | F32: =+F31+D32-E32 -> 2440705
C33: 26 | D33: =+VENTAS!E87 -> 666500 | E33: =+VENTAS!G87 -> 507612 | F33: =+F32+D33-E33 -> 2599593
C34: 27 | D34: =+VENTAS!E90 -> 859000 | E34: =+VENTAS!G90 -> 500590 | F34: =+F33+D34-E34 -> 2958003
C35: 28 | D35: =+VENTAS!E93 -> 341000 | E35: =+VENTAS!G93 -> 561972 | F35: =+F34+D35-E35 -> 2737031
C36: 29 | D36: =+VENTAS!E96 -> 561000 | E36: =+VENTAS!G96 -> 267614 | F36: =+F35+D36-E36 -> 3030417
C37: 30 | D37: =+VENTAS!E99 -> 618000 | E37: =+VENTAS!G99 -> 326172 | F37: =+F36+D37-E37 -> 3322245
C38: 31 | D38: =+VENTAS!E102 -> 867000 | E38: =+VENTAS!G102 -> 396124 | F38: =+F37+D38-E38 -> 3793121
C39: TOTAL | D39: =SUM(D8:D38) -> 20159700 | E39: =SUM(E8:E38) -> 16366579 | F39: =+F37+D38-E38 -> 3793121

Sheet ACCESORIOS
A2: DIA | B2: MODELO | C2: FORMA PAGO | D2: VENTAS $ | H2: EFECTIVO
A3: 1 | H3: NEKI
H4: DAVIPLATA
H5: TARJETA
A14: TOTAL | D14: =SUM(D3:D13) -> 0
A15: DIA | B15: MODELO | C15: FORMA PAGO | D15: VENTAS $
A16: 2
A27: TOTAL | D27: =SUM(D16:D26) -> 0
A28: DIA | B28: MODELO | C28: FORMA PAGO | D28: VENTAS $
A29: 3
A40: TOTAL | D40: =SUM(D29:D39) -> 0
A41: DIA | B41: MODELO | C41: FORMA PAGO | D41: VENTAS $
A42: 4 | B42: accesorios | C42: NEKI | D42: 10000
A53: TOTAL | D53: =SUM(D42:D52) -> 10000
A54: DIA | B54: MODELO | C54: FORMA PAGO | D54: VENTAS $
A55: 5
A66: TOTAL | D66: =SUM(D55:D65) -> 0
A67: DIA | B67: MODELO | C67: FORMA PAGO | D67: VENTAS $
A68: 6
A79: TOTAL | D79: =SUM(D68:D78) -> 0
A80: DIA | B80: MODELO | C80: FORMA PAGO | D80: VENTAS $
A81: 7
A92: TOTAL | D92: =SUM(D81:D91) -> 0
A93: DIA | B93: MODELO | C93: FORMA PAGO | D93: VENTAS $
A94: 8
A105: TOTAL | D105: =SUM(D94:D104) -> 0
A106: DIA | B106: MODELO | C106: FORMA PAGO | D106: VENTAS $
A107: 9
A118: TOTAL | D118: =SUM(D107:D117) -> 0
A119: DIA | B119: MODELO | C119: FORMA PAGO | D119: VENTAS $
A120: 10
A131: TOTAL | D131: =SUM(D120:D130) -> 0
A132: DIA | B132: MODELO | C132: FORMA PAGO | D132: VENTAS $
A133: 11
A144: TOTAL | D144: =SUM(D133:D143) -> 0
A145: DIA | B145: MODELO | C145: FORMA PAGO | D145: VENTAS $
A146: 12
A157: TOTAL | D157: =SUM(D146:D156) -> 0
A158: DIA | B158: MODELO | C158: FORMA PAGO | D158: VENTAS $
A159: 13 | B159: argollitas | C159: efectivo | D159: 6000
...

Sheet CAJA FUERTE
I2: DIA | J2: BASE INICIAL | K2: VENTA EFEC | L2: VENTA TARJETA | M2: EGRESOS | N2: BASE FINAL | O2: CF
O3: =F6 -> 101350
I4: 1 | J4: 1300000 | K4: =VENTAS!E10 -> 503500 | N4: 1300000 | O4: =O3+K4-M4-N4 -> -695150
A5: DIA | C5: DEPOSITO | D5: RETIRO AUT. | E5: BANCO | F5: SALDO | I5: 2 | J5: 1300000 | K5: =VENTAS!E13 -> 552500 | N5: 1300000 | O5: =+J5+K5-M5-N5 -> 552500
A6: 1 | B6: SALDO MES ANTERIOR | C6: 101350 | D6: 0 | F6: =+C6 -> 101350 | I6: 3 | J6: 1300001 | K6: =VENTAS!E14 -> 288700 | N6: 1300001 | O6: =+J6+K6-M6-N6 -> 288700
B7: DEPOSITO CR | C7: 125000 | D7: 0 | E7: 0 | F7: =+C7-D7-E7+F6 -> 226350 | I7: 4 | J7: 1300002 | K7: =VENTAS!E15 -> 841200 | N7: 1300002 | O7: =+J7+K7-M7-N7 -> 841200
B8: DEPOSITO CR | C8: 378500 | D8: 0 | E8: 0 | F8: =+C8-D8-E8+F7 -> 604850 | I8: 5 | J8: 1300003 | K8: =VENTAS!E16 -> 742000 | N8: 1300003 | O8: =+J8+K8-M8-N8 -> 742000
B9: RT REPOSICION | C9: 0 | D9: 447000 | E9: 0 | F9: =+C9-D9-E9+F8 -> 157850 | I9: 6 | J9: 1300004 | K9: =VENTAS!E17 -> 171000 | N9: 1300004 | O9: =+J9+K9-M9-N9 -> 171000
C10: 0 | D10: 0 | E10: 0 | F10: =+C10-D10-E10+F9 -> 157850 | I10: 7 | J10: 1300005 | K10: =VENTAS!E18 -> 913000 | N10: 1300005 | O10: =+J10+K10-M10-N10 -> 913000
B11: ACCESORIOS | C11: =+SUMIF(ACCESORIOS!C3:D13,ACCESORIOS!H2,ACCESORIOS!D3:D13) -> 0 | D11: 0 | E11: 0 | F11: =+C11-D11-E11+F10 -> 157850 | I11: 8 | J11: 1300011 | K11: =VENTAS!E24 -> 903000 | N11: 1300011 | O11: =+J11+K11-M11-N11 -> 903000
A12: TOTAL | C12: =SUM(C6:C11) -> 604850 | D12: =SUM(D6:D11) -> 447000 | E12: =SUM(E6:E11) -> 0 | F12: =F11 -> 157850 | I12: 9 | J12: 1300012 | K12: =VENTAS!E25 -> 101000 | N12: 1300012 | O12: =+J12+K12-M12-N12 -> 101000
A13: 2 | B13: DEPOSITO CR | C13: 71000 | D13: 0 | E13: 0 | F13: =+C13-D13-E13+F12 -> 228850 | I13: 10 | J13: 1300013 | K13: =VENTAS!E26 -> 185700 | N13: 1300013 | O13: =+J13+K13-M13-N13 -> 185700
B14: DEPOSITO CR | C14: 481500 | D14: 0 | E14: 0 | F14: =+C14-D14-E14+F13 -> 710350 | I14: 11 | J14: 1300014 | K14: =VENTAS!E27 -> 286700 | N14: 1300014
B15: RT REPOSICION | C15: 0 | D15: 346500 | E15: 0 | F15: =+C15-D15-E15+F14 -> 363850 | I15: 12 | J15: 1300015 | K15: =VENTAS!E28 -> 424000 | N15: 1300015 | O15: =+J15+K15-M15-N15 -> 424000
B16: RETIRO AUTORIZADO JUAN VILLABONA | C16: 0 | D16: 50000 | E16: 0 | F16: =+C16-D16-E16+F15 -> 313850 | I16: 13 | J16: 1300016 | K16: =VENTAS!E29 -> 195000 | N16: 1300016
B17: ACCESORIOS | C17: =+SUMIF(ACCESORIOS!C16:D26,ACCESORIOS!H2,ACCESORIOS!D16:D26) -> 0 | D17: 0 | E17: 0 | F17: =+C17-D17-E17+F16 -> 313850 | I17: 14 | J17: 1300017 | K17: =VENTAS!E30 -> 619000 | N17: 1300017 | O17: =+J17+K17-M17-N17 -> 619000 | AD17: Arriendo
A18: TOTAL | C18: =SUM(C13:C17) -> 552500 | D18: =SUM(D13:D17) -> 396500 | E18: =SUM(E13:E17) -> 0 | F18: =F17 -> 313850 | I18: 15 | J18: 1300018 | K18: =VENTAS!E31 -> 387000 | N18: 1300018 | O18: =+J18+K18-M18-N18 -> 387000 | AD18: Deposito 24079920959
A19: 3 | B19: DEPOSITO CR | C19: 94000 | D19: 0 | E19: 0 | F19: =+C19-D19-E19+F18 -> 407850 | I19: 16 | J19: 1300019 | K19: =VENTAS!E32 -> 165000 | N19: 1300019 | O19: =+J19+K19-M19-N19 -> 165000 | AD19: Servicio luz
B20: DEPOSITO CR | C20: 648000 | D20: 0 | E20: 0 | F20: =+C20-D20-E20+F19 -> 1055850 | I20: 17 | J20: 1300020 | K20: =VENTAS!E33 -> 552000 | N20: 1300020 | AD20: Servicio agua
B21: RT REPOSICION | C21: 0 | D21: 595200 | E21: 0 | F21: =+C21-D21-E21+F20 -> 460650 | I21: 18 | J21: 1300021 | K21: =VENTAS!E34 -> 599500 | N21: 1300021
B22: SOBRANTE APROBADO | C22: 54000 | D22: 0 | E22: 0 | F22: =+C22-D22-E22+F21 -> 514650 | I22: 19 | J22: 1300022 | K22: =VENTAS!E35 -> 128000 | N22: 1300022 | O22: =+J22+K22-M22-N22 -> 128000 | AD22: Servicio gas
B23: ACCESORIOS | C23: =+SUMIF(ACCESORIOS!C29:D39,ACCESORIOS!H2,ACCESORIOS!D29:D39) -> 0 | D23: 0 | E23: 0 | F23: =+C23-D23-E23+F22 -> 514650 | I23: 20 | J23: 1300023 | K23: =VENTAS!E36 -> 727500 | N23: 1300023 | O23: =+J23+K23-M23-N23 -> 727500 | AD23: Deposito 24070185038
A24: TOTAL | C24: =SUM(C19:C23) -> 796000 | D24: =SUM(D19:D23) -> 595200 | E24: =SUM(E19:E23) -> 0 | F24: =F23 -> 514650 | I24: 21 | J24: 1300024 | K24: =VENTAS!E37 -> 623000 | N24: 1300024 | O24: =+J24+K24-M24-N24 -> 623000 | AD24: RETIRO AUTORIZADO SUSAN RIVERA
A25: 4 | B25: DEPOSITO CR | C25: 113700 | D25: 0 | E25: 0 | F25: =+C25-D25-E25+F24 -> 628350 | I25: 22 | J25: 1300025 | K25: =VENTAS!E38 -> 140000 | N25: 1300025 | O25: =+J25+K25-M25-N25 -> 140000 | AD25: RETIRO AUTORIZADO JUAN VILLABONA
B26: DEPOSITO CR | C26: 534500 | D26: 0 | E26: 0 | F26: =+C26-D26-E26+F25 -> 1162850 | I26: 23 | J26: 1300026 | K26: =VENTAS!E39 -> 763000 | N26: 1300026 | AD26: SALDO MES ANTERIOR
B27: RT REPOSICION | C27: 0 | D27: 456500 | E27: 0 | F27: =+C27-D27-E27+F26 -> 706350 | I27: 24 | J27: 1300027 | K27: =VENTAS!E40 -> 714500 | N27: 1300027
C28: 0 | D28: 0 | E28: 0 | F28: =+C28-D28-E28+F27 -> 706350 | I28: 25 | J28: 1300028 | K28: =VENTAS!E41 -> 335500 | N28: 1300028 | O28: =+J28+K28-M28-N28 -> 335500 | AD28: DEPOSITO CR
B29: ACCESORIOS | C29: =+SUMIF(ACCESORIOS!C42:D52,ACCESORIOS!H2,ACCESORIOS!D42:D52) -> 0 | D29: 0 | E29: 0 | F29: =+C29-D29-E29+F28 -> 706350 | I29: 26 | J29: 1300000 | K29: =VENTAS!E82 -> 494900 | N29: 1300000 | O29: =+J29+K29-M29-N29 -> 494900 | AD29: RT REPOSICION
A30: TOTAL | C30: =SUM(C25:C29) -> 648200 | D30: =SUM(D25:D29) -> 456500 | E30: =SUM(E25:E29) -> 0 | F30: =F29 -> 706350 | I30: 27 | J30: 1300001 | K30: =VENTAS!E83 -> 262000 | N30: 1300001 | O30: =+J30+K30-M30-N30 -> 262000 | AD30: FONDO R
A31: 5 | B31: DEPOSITO CR | C31: 199000 | D31: 0 | E31: 0 | F31: =+C31-D31-E31+F30 -> 905350 | I31: 28 | J31: 1300002 | K31: =VENTAS!E84 -> 756900 | N31: 1300002 | O31: =+J31+K31-M31-N31 -> 756900 | AD31: ACCESORIOS
B32: DEPOSITO CR | C32: =368000+16000 -> 384000 | D32: 0 | E32: 0 | F32: =+C32-D32-E32+F31 -> 1289350 | I32: 29 | J32: 1300003 | K32: =VENTAS!E85 -> 528500 | N32: 1300003
B33: RT REPOSICION | C33: 0 | D33: 525100 | E33: 0 | F33: =+C33-D33-E33+F32 -> 764250 | I33: 30 | J33: 1300004 | K33: =VENTAS!E86 -> 138000 | N33: 1300004
B34: RETIRO AUTORIZADO JUAN VILLABONA | C34: 0 | D34: 650000 | E34: 0 | F34: =+C34-D34-E34+F33 -> 114250 | I34: 31 | J34: 1300005 | K34: =VENTAS!E87 -> 666500 | N34: 1300005 | O34: =+J34+K34-M34-N34 -> 666500 | AD34: FALTANTE APROBADO
B35: ACCESORIOS | C35: =+SUMIF(ACCESORIOS!C55:D65,ACCESORIOS!H2,ACCESORIOS!D55:D65) -> 0 | D35: 0 | E35: 0 | F35: =+C35-D35-E35+F34 -> 114250 | O35: =+J35+K35-M35-N35 -> 0 | AD35: SOBRANTE APROBADO
A36: TOTAL | C36: =SUM(C31:C35) -> 583000 | D36: =SUM(D31:D35) -> 1175100 | E36: =SUM(E31:E35) -> 0 | F36: =F35 -> 114250 | O36: =+J36+K36-M36-N36 -> 0
A37: 6 | B37: DEPOSITO CR | C37: 17000 | D37: 0 | E37: 0 | F37: =+C37-D37-E37+F36 -> 131250 | O37: =+J37+K37-M37-N37 -> 0
B38: DEPOSITO CR | C38: 84000 | D38: 0 | E38: 0 | F38: =+C38-D38-E38+F37 -> 215250
B39: RT REPOSICION | C39: 0 | D39: 137500 | E39: 0 | F39: =+C39-D39-E39+F38 -> 77750
C40: 0 | D40: 0 | E40: 0 | F40: =+C40-D40-E40+F39 -> 77750
B41: ACCESORIOS | C41: =+SUMIF(ACCESORIOS!C68:D78,ACCESORIOS!H2,ACCESORIOS!D68:D78) -> 0 | D41: 0 | E41: 0 | F41: =+C41-D41-E41+F40 -> 77750
...

Sheet RESUMEN GASTOS
A2: SUSAN DANIELA RIVERA TORREALBA
A3: C.C.1.140.418.986
A4: RESUMEN GASTOS
A5: MES DE FEBRERO 2022
A7: TERCERO | B7: DESCRIPCION | C7: COSTO | D7: GASTO | E7: TOTAL
A53: TOTALES | C53: =SUM(C8:C52) -> 0 | D53: =SUM(D8:D52) -> 0 | E53: =SUM(E8:E52) -> 0
